"""
Authentication Edge Cases and Network Connectivity Failures - Iteration 2 Audit

This comprehensive test file covers the authentication edge cases and network 
connectivity issues that contribute to the complete authentication system failure
identified in Iteration 2:

**CRITICAL EDGE CASES & NETWORK ISSUES:**
1. Token expiration handling completely broken (no refresh mechanism)
2. Invalid credential scenarios causing system crashes
3. Network connectivity failures between services
4. Auth service completely unreachable or down
5. Service account permissions missing or insufficient  
6. JWT signing key mismatches across services
7. Network policies blocking authentication traffic
8. SSL/TLS handshake failures in staging/production
9. DNS resolution failures for authentication services
10. Load balancer/proxy authentication configuration errors

**EXPECTED TO FAIL**: These tests expose the fragile authentication infrastructure
leading to the 6.2+ second latency and 100% 403 failure rate

Network Architecture Tested:
- Frontend → Load Balancer → Backend
- Backend → Auth Service
- Auth Service → Database
- Service → Service mesh authentication
- External OAuth providers
- GCP service authentication

Root Causes (Edge Cases & Network):
- No graceful handling of authentication edge cases
- Network timeouts causing authentication failures
- No fallback mechanisms when auth services unreachable
- Certificate validation failures in production environments  
- Service discovery failures causing auth routing issues
"""

import asyncio
import pytest
import httpx
import socket
import ssl
import time
import dns.resolver
from unittest.mock import Mock, patch, AsyncMock
from datetime import datetime, timedelta
import jwt
import subprocess

from test_framework.base_e2e_test import BaseE2ETest


@pytest.mark.e2e
@pytest.mark.critical
class TestAuthenticationEdgeCasesAndNetworkFailures(BaseE2ETest):
    """Test authentication edge cases and network connectivity failures"""

    def setup_method(self):
        """Set up comprehensive edge case test environment"""
        super().setup_method()
        self.services = {
            'frontend': 'http://localhost:3000',
            'backend': 'http://localhost:8000',
            'auth_service': 'http://localhost:8080',
            'load_balancer': 'http://localhost:8090'
        }
        self.timeout_threshold = 2.0  # Authentication should complete within 2 seconds
        self.network_test_hosts = [
            'auth.staging.netrasystems.ai',
            'api.staging.netrasystems.ai',
            'app.staging.netrasystems.ai'
        ]

    @pytest.mark.critical
    async def test_token_expiration_handling_completely_broken(self):
        """
        EXPECTED TO FAIL - CRITICAL TOKEN EXPIRATION ISSUE
        Expired tokens should trigger refresh mechanism but system has no token refresh
        Root cause: No token refresh mechanism implemented, expired tokens cause permanent failures
        """
        # Create expired token
        expired_token_payload = {
            'sub': 'test-user-expired',
            'iat': (datetime.utcnow() - timedelta(hours=2)).timestamp(),
            'exp': (datetime.utcnow() - timedelta(hours=1)).timestamp(),  # Expired 1 hour ago
            'iss': 'netra-auth',
            'aud': 'netra-backend'
        }
        
        expired_token = jwt.encode(expired_token_payload, 'test-key', algorithm='HS256')
        
        async with httpx.AsyncClient() as client:
            try:
                # Attempt to use expired token - should trigger refresh mechanism
                response = await client.get(
                    f"{self.services['backend']}/api/threads",
                    headers={
                        'Authorization': f'Bearer {expired_token}',
                        'Content-Type': 'application/json',
                    },
                    timeout=5.0
                )
                
                # Should either:
                # 1. Automatically refresh token and succeed (200)
                # 2. Return token refresh redirect/instruction (401 with refresh info)
                if response.status_code == 401:
                    response_data = response.json()
                    # Should provide token refresh guidance
                    assert 'refresh_token' in response_data or 'refresh_url' in response_data
                    assert response_data.get('error_code') == 'TOKEN_EXPIRED'
                    assert 'refresh' in response_data.get('message', '').lower()
                else:
                    # Should succeed with automatic refresh
                    assert response.status_code == 200
                
            except httpx.TimeoutException:
                pytest.fail("Token expiration handling timeout - no refresh mechanism")
            except Exception as e:
                pytest.fail(f"Token expiration handling failed: {str(e)}")

    @pytest.mark.critical
    async def test_invalid_credential_scenarios_causing_system_crashes(self):
        """
        EXPECTED TO FAIL - CRITICAL INVALID CREDENTIALS ISSUE
        Invalid credentials should be handled gracefully but cause system instability
        Root cause: Invalid credential scenarios not properly handled, causing crashes
        """
        invalid_credential_scenarios = [
            ('malformed_jwt', 'not.a.valid.jwt.token.structure'),
            ('empty_token', ''),
            ('null_token', None),
            ('sql_injection_attempt', "'; DROP TABLE users; --"),
            ('xss_attempt', '<script>alert("auth")</script>'),
            ('buffer_overflow', 'A' * 10000),  # Very long token
            ('invalid_base64', 'invalid-base64-!@#$%'),
            ('wrong_algorithm', jwt.encode({'sub': 'test'}, 'key', algorithm='HS512')),  # Wrong algorithm
        ]
        
        async with httpx.AsyncClient() as client:
            for scenario_name, invalid_credential in invalid_credential_scenarios:
                try:
                    start_time = time.time()
                    
                    # System should handle invalid credentials gracefully
                    response = await client.get(
                        f"{self.services['backend']}/api/threads",
                        headers={
                            'Authorization': f'Bearer {invalid_credential}' if invalid_credential else '',
                            'Content-Type': 'application/json',
                            'X-Test-Scenario': scenario_name
                        },
                        timeout=3.0
                    )
                    
                    end_time = time.time()
                    duration = end_time - start_time
                    
                    # Should handle invalid credentials quickly and gracefully
                    assert response.status_code in [400, 401], f"Scenario {scenario_name}: Should return 400/401, got {response.status_code}"
                    assert duration < 1.0, f"Scenario {scenario_name}: Took {duration:.2f}s to handle invalid credential"
                    
                    response_data = response.json()
                    assert 'error' in response_data, f"Scenario {scenario_name}: Should return error message"
                    assert response_data.get('error') != 'Internal Server Error', f"Scenario {scenario_name}: Should not crash server"
                    
                except httpx.TimeoutException:
                    pytest.fail(f"Invalid credential scenario '{scenario_name}' caused timeout/hang")
                except httpx.ReadTimeout:
                    pytest.fail(f"Invalid credential scenario '{scenario_name}' caused system crash")
                except Exception as e:
                    pytest.fail(f"Invalid credential scenario '{scenario_name}' caused unexpected error: {str(e)}")

    @pytest.mark.critical
    async def test_network_connectivity_failures_between_services(self):
        """
        EXPECTED TO FAIL - CRITICAL NETWORK CONNECTIVITY ISSUE
        Services should handle network connectivity failures gracefully
        Root cause: No resilience to network failures, causing authentication to fail completely
        """
        # Test network connectivity between services
        service_connections = [
            ('frontend', 'backend', '/api/health'),
            ('backend', 'auth_service', '/auth/health'),
            ('backend', 'backend', '/api/health')  # Self-connectivity check
        ]
        
        connectivity_issues = []
        
        for source, target, endpoint in service_connections:
            try:
                # Test basic connectivity
                start_time = time.time()
                
                async with httpx.AsyncClient() as client:
                    response = await client.get(
                        f"{self.services[target]}{endpoint}",
                        headers={
                            'X-Source-Service': source,
                            'X-Connectivity-Test': 'true'
                        },
                        timeout=3.0
                    )
                    
                    end_time = time.time()
                    duration = end_time - start_time
                    
                    # Should connect successfully and quickly
                    assert response.status_code == 200, f"{source} → {target}: Connection failed with {response.status_code}"
                    assert duration < 1.0, f"{source} → {target}: Connection took {duration:.2f}s (should be < 1.0s)"
                    
                    health_data = response.json()
                    assert health_data.get('status') == 'healthy', f"{source} → {target}: Service not healthy"
                    
            except httpx.ConnectError as e:
                connectivity_issues.append(f"{source} → {target}: Connection error - {str(e)}")
            except httpx.TimeoutException:
                connectivity_issues.append(f"{source} → {target}: Connection timeout")
            except Exception as e:
                connectivity_issues.append(f"{source} → {target}: Network error - {str(e)}")
        
        # Should NOT have network connectivity issues
        assert len(connectivity_issues) == 0, f"Network connectivity failures: {connectivity_issues}"

    @pytest.mark.critical
    async def test_auth_service_completely_unreachable_or_down(self):
        """
        EXPECTED TO FAIL - CRITICAL AUTH SERVICE AVAILABILITY ISSUE
        System should handle auth service being down with graceful degradation
        Root cause: No fallback when auth service unreachable, complete system failure
        """
        # Test various auth service failure scenarios
        auth_failure_scenarios = [
            ('connection_refused', httpx.ConnectError('Connection refused')),
            ('dns_resolution_failed', httpx.ConnectError('DNS resolution failed')),
            ('service_timeout', httpx.TimeoutException('Auth service timeout')),
            ('service_overloaded', httpx.ReadTimeout('Auth service overloaded'))
        ]
        
        async with httpx.AsyncClient() as client:
            for scenario_name, mock_exception in auth_failure_scenarios:
                with patch('httpx.AsyncClient.get', side_effect=mock_exception):
                    try:
                        # Should have fallback mechanism when auth service is down
                        response = await client.get(
                            f"{self.services['backend']}/api/threads",
                            headers={
                                'Authorization': 'Bearer fallback-test-token',
                                'X-Auth-Fallback-Test': scenario_name,
                                'Content-Type': 'application/json'
                            },
                            timeout=5.0
                        )
                        
                        # Should either:
                        # 1. Use cached authentication (200)
                        # 2. Return graceful degradation message (503 with retry info)
                        if response.status_code == 503:
                            response_data = response.json()
                            assert 'retry_after' in response_data, f"Scenario {scenario_name}: Should provide retry guidance"
                            assert 'fallback' in response_data.get('message', '').lower()
                        else:
                            assert response.status_code == 200, f"Scenario {scenario_name}: Should use fallback auth"
                        
                    except Exception as e:
                        pytest.fail(f"Auth service down scenario '{scenario_name}' not handled gracefully: {str(e)}")

    @pytest.mark.critical
    async def test_service_account_permissions_missing_or_insufficient(self):
        """
        EXPECTED TO FAIL - CRITICAL SERVICE ACCOUNT PERMISSIONS ISSUE
        System should detect and report service account permission issues clearly
        Root cause: Service account lacks required permissions, causing silent failures
        """
        permission_scenarios = [
            ('missing_read_permission', 'netra.backend.read'),
            ('missing_auth_permission', 'netra.auth.validate'),
            ('missing_user_permission', 'netra.users.access'),
            ('missing_thread_permission', 'netra.threads.manage'),
            ('expired_service_account', 'service_account_expired'),
            ('revoked_permissions', 'permissions_revoked')
        ]
        
        async with httpx.AsyncClient() as client:
            for scenario_name, missing_permission in permission_scenarios:
                try:
                    response = await client.get(
                        f"{self.services['backend']}/api/threads",
                        headers={
                            'Authorization': 'Bearer service-account-token',
                            'X-Service-Account': 'netra-test@staging.iam.gserviceaccount.com',
                            'X-Permission-Test': scenario_name,
                            'X-Required-Permission': missing_permission
                        },
                        timeout=3.0
                    )
                    
                    # Should clearly identify permission issues
                    if response.status_code == 403:
                        response_data = response.json()
                        assert 'permission' in response_data.get('error', '').lower()
                        assert 'required_permissions' in response_data
                        assert missing_permission in response_data.get('required_permissions', [])
                        assert 'service_account' in response_data
                    else:
                        assert response.status_code == 200, f"Scenario {scenario_name}: Should succeed with proper permissions"
                    
                except Exception as e:
                    pytest.fail(f"Service account permission scenario '{scenario_name}' failed: {str(e)}")

    @pytest.mark.critical
    async def test_jwt_signing_key_mismatches_across_services(self):
        """
        EXPECTED TO FAIL - CRITICAL JWT KEY SYNC ISSUE
        JWT signing key mismatches should be detected and reported clearly
        Root cause: Services using different JWT signing keys, causing signature verification failures
        """
        # Test JWT tokens signed with different keys
        key_mismatch_scenarios = [
            ('old_key', 'old-signing-key-deprecated'),
            ('wrong_key', 'wrong-signing-key-different-env'),
            ('rotated_key', 'rotated-key-not-synced'),
            ('dev_key_in_staging', 'development-key-in-staging')
        ]
        
        for scenario_name, signing_key in key_mismatch_scenarios:
            # Create token with mismatched key
            token_payload = {
                'sub': f'test-user-{scenario_name}',
                'iat': datetime.utcnow().timestamp(),
                'exp': (datetime.utcnow() + timedelta(minutes=15)).timestamp(),
                'iss': 'netra-auth',
                'aud': 'netra-backend'
            }
            
            mismatched_token = jwt.encode(token_payload, signing_key, algorithm='HS256')
            
            async with httpx.AsyncClient() as client:
                try:
                    response = await client.get(
                        f"{self.services['backend']}/api/threads",
                        headers={
                            'Authorization': f'Bearer {mismatched_token}',
                            'X-JWT-Key-Test': scenario_name,
                            'Content-Type': 'application/json'
                        },
                        timeout=3.0
                    )
                    
                    # Should clearly identify JWT signature issues
                    if response.status_code == 401:
                        response_data = response.json()
                        assert 'signature' in response_data.get('error', '').lower() or 'key' in response_data.get('error', '').lower()
                        assert 'jwt' in response_data.get('error_type', '').lower()
                        assert 'key_id' in response_data or 'signing_key' in response_data
                    else:
                        pytest.fail(f"JWT key mismatch scenario '{scenario_name}' should be rejected")
                        
                except Exception as e:
                    pytest.fail(f"JWT key mismatch scenario '{scenario_name}' caused unexpected error: {str(e)}")

    @pytest.mark.critical  
    def test_network_policies_blocking_authentication_traffic(self):
        """
        EXPECTED TO FAIL - CRITICAL NETWORK POLICY ISSUE
        Network policies should allow authentication traffic between services
        Root cause: Network policies blocking authentication-related traffic
        """
        # Test network connectivity to authentication services
        auth_network_tests = [
            ('auth_service_port', 'localhost', 8080),
            ('backend_service_port', 'localhost', 8000), 
            ('frontend_service_port', 'localhost', 3000),
            ('postgres_port', 'localhost', 5432),
            ('redis_port', 'localhost', 6379)
        ]
        
        network_policy_issues = []
        
        for test_name, host, port in auth_network_tests:
            try:
                # Test TCP connectivity to authentication-related ports
                sock = socket.socket(socket.AF_INET, socket.SOCK_STREAM)
                sock.settimeout(3.0)
                result = sock.connect_ex((host, port))
                sock.close()
                
                if result != 0:
                    network_policy_issues.append(f"{test_name}: Cannot connect to {host}:{port} (result: {result})")
                    
            except socket.timeout:
                network_policy_issues.append(f"{test_name}: Connection timeout to {host}:{port}")
            except Exception as e:
                network_policy_issues.append(f"{test_name}: Network error to {host}:{port} - {str(e)}")
        
        # Should NOT have network policy blocking issues
        assert len(network_policy_issues) == 0, f"Network policy blocking authentication traffic: {network_policy_issues}"

    @pytest.mark.critical
    async def test_ssl_tls_handshake_failures_in_staging_production(self):
        """
        EXPECTED TO FAIL - CRITICAL SSL/TLS ISSUE
        SSL/TLS handshake should succeed for staging/production authentication endpoints
        Root cause: SSL certificate issues or TLS configuration errors
        """
        # Test SSL/TLS connectivity to staging endpoints
        ssl_test_endpoints = [
            'https://auth.staging.netrasystems.ai',
            'https://api.staging.netrasystems.ai',
            'https://app.staging.netrasystems.ai'
        ]
        
        ssl_handshake_issues = []
        
        async with httpx.AsyncClient(verify=True) as client:  # Enable SSL verification
            for endpoint in ssl_test_endpoints:
                try:
                    response = await client.get(
                        f"{endpoint}/health",
                        headers={'User-Agent': 'Netra-SSL-Test'},
                        timeout=5.0
                    )
                    
                    # Should establish SSL connection successfully
                    assert response.status_code in [200, 404], f"{endpoint}: SSL handshake failed with {response.status_code}"
                    
                except httpx.ConnectError as e:
                    if 'certificate' in str(e).lower() or 'ssl' in str(e).lower():
                        ssl_handshake_issues.append(f"{endpoint}: SSL certificate error - {str(e)}")
                    else:
                        ssl_handshake_issues.append(f"{endpoint}: Connection error - {str(e)}")
                        
                except httpx.TimeoutException:
                    ssl_handshake_issues.append(f"{endpoint}: SSL handshake timeout")
                    
                except Exception as e:
                    ssl_handshake_issues.append(f"{endpoint}: SSL error - {str(e)}")
        
        # Should NOT have SSL/TLS handshake issues
        assert len(ssl_handshake_issues) == 0, f"SSL/TLS handshake failures: {ssl_handshake_issues}"

    @pytest.mark.medium
    def test_dns_resolution_failures_for_authentication_services(self):
        """
        EXPECTED TO FAIL - MEDIUM DNS RESOLUTION ISSUE
        DNS resolution should work for all authentication service endpoints
        Root cause: DNS resolution failing for authentication service hostnames
        """
        dns_resolution_issues = []
        
        for host in self.network_test_hosts:
            try:
                # Test DNS resolution
                start_time = time.time()
                answers = dns.resolver.resolve(host, 'A')
                end_time = time.time()
                
                dns_duration = end_time - start_time
                
                # Should resolve quickly
                assert len(answers) > 0, f"DNS resolution failed for {host}: No A records found"
                assert dns_duration < 2.0, f"DNS resolution slow for {host}: {dns_duration:.2f}s"
                
                # Verify resolved IPs are valid
                for answer in answers:
                    ip_address = str(answer)
                    assert len(ip_address.split('.')) == 4, f"Invalid IP address resolved for {host}: {ip_address}"
                    
            except dns.resolver.NXDOMAIN:
                dns_resolution_issues.append(f"{host}: DNS NXDOMAIN - domain does not exist")
            except dns.resolver.Timeout:
                dns_resolution_issues.append(f"{host}: DNS resolution timeout")
            except Exception as e:
                dns_resolution_issues.append(f"{host}: DNS resolution error - {str(e)}")
        
        # Should NOT have DNS resolution issues
        assert len(dns_resolution_issues) == 0, f"DNS resolution failures: {dns_resolution_issues}"

    @pytest.mark.critical
    async def test_load_balancer_proxy_authentication_configuration_errors(self):
        """
        EXPECTED TO FAIL - CRITICAL LOAD BALANCER CONFIG ISSUE
        Load balancer should properly proxy authentication requests
        Root cause: Load balancer/proxy not configured for authentication passthrough
        """
        async with httpx.AsyncClient() as client:
            try:
                # Test authentication through load balancer
                response = await client.get(
                    f"{self.services['load_balancer']}/api/threads",
                    headers={
                        'Authorization': 'Bearer load-balancer-test-token',
                        'X-Forwarded-For': '192.168.1.100',
                        'X-Real-IP': '192.168.1.100',
                        'Host': 'api.netrasystems.ai'
                    },
                    timeout=5.0
                )
                
                # Load balancer should properly forward authentication
                if response.status_code == 502:
                    response_data = response.json()
                    assert 'proxy' not in response_data.get('error', '').lower()
                    assert 'gateway' not in response_data.get('error', '').lower()
                elif response.status_code == 401:
                    response_data = response.json()
                    # Should receive proper authentication error, not proxy error
                    assert 'authentication' in response_data.get('error', '').lower()
                else:
                    assert response.status_code == 200, f"Load balancer proxy failed with {response.status_code}"
                
            except httpx.ConnectError:
                pytest.fail("Load balancer not accessible for authentication proxy test")
            except Exception as e:
                pytest.fail(f"Load balancer authentication configuration error: {str(e)}")

    @pytest.mark.medium
    async def test_authentication_circuit_breaker_not_implemented(self):
        """
        EXPECTED TO FAIL - MEDIUM CIRCUIT BREAKER ISSUE
        Authentication should have circuit breaker for resilience
        Root cause: No circuit breaker implemented for authentication failures
        """
        # Simulate multiple authentication failures to trigger circuit breaker
        failure_count = 10
        circuit_breaker_triggered = False
        
        async with httpx.AsyncClient() as client:
            for attempt in range(failure_count):
                try:
                    response = await client.get(
                        f"{self.services['backend']}/api/threads",
                        headers={
                            'Authorization': 'Bearer circuit-breaker-test-invalid-token',
                            'X-Circuit-Breaker-Test': f'attempt-{attempt + 1}',
                            'Content-Type': 'application/json'
                        },
                        timeout=2.0
                    )
                    
                    if response.status_code == 503:
                        response_data = response.json()
                        if 'circuit' in response_data.get('error', '').lower():
                            circuit_breaker_triggered = True
                            break
                    
                    # Brief delay between attempts
                    await asyncio.sleep(0.1)
                    
                except Exception as e:
                    continue
        
        # Should trigger circuit breaker after multiple failures
        assert circuit_breaker_triggered, f"Circuit breaker not triggered after {failure_count} authentication failures"

    async def teardown_method(self):
        """Clean up after edge case and network tests"""
        await super().teardown_method()