# REMOVED_SYNTAX_ERROR: '''
# REMOVED_SYNTAX_ERROR: Mission Critical Test: Circuit Breaker Recovery Verification

# REMOVED_SYNTAX_ERROR: This test verifies that the circuit breaker fix works correctly and that
# REMOVED_SYNTAX_ERROR: circuit breakers recover automatically after the timeout period.

# REMOVED_SYNTAX_ERROR: CRITICAL: This tests the fix for the systemic permanent failure state bug
# REMOVED_SYNTAX_ERROR: discovered on 2025-09-05 where MockCircuitBreaker would open permanently
# REMOVED_SYNTAX_ERROR: on ANY error with NO recovery mechanism.

# REMOVED_SYNTAX_ERROR: Cross-reference: SPEC/learnings/permanent_failure_state_pattern_20250905.xml
# REMOVED_SYNTAX_ERROR: '''

import asyncio
import time
import pytest
from shared.isolated_environment import IsolatedEnvironment

# REMOVED_SYNTAX_ERROR: from netra_backend.app.clients.auth_client_cache import ( )
AuthCircuitBreakerManager,
MockCircuitBreaker

from netra_backend.app.clients.auth_client_core import AuthServiceClient
# REMOVED_SYNTAX_ERROR: from netra_backend.app.core.resilience.unified_circuit_breaker import ( )
UnifiedCircuitBreaker,
UnifiedCircuitConfig,
UnifiedCircuitBreakerState

from netra_backend.app.core.unified_error_handler import UnifiedErrorHandler
from netra_backend.app.db.database_manager import DatabaseManager
from shared.isolated_environment import get_env


# REMOVED_SYNTAX_ERROR: class TestCircuitBreakerRecovery:
    # REMOVED_SYNTAX_ERROR: """Test suite for circuit breaker recovery mechanisms."""

    # Removed problematic line: @pytest.mark.asyncio
    # Removed problematic line: async def test_mock_circuit_breaker_recovery(self):
        # REMOVED_SYNTAX_ERROR: """Verify MockCircuitBreaker recovers after timeout (CRITICAL FIX)."""
        # Create MockCircuitBreaker with our fix
        # REMOVED_SYNTAX_ERROR: breaker = MockCircuitBreaker("test_breaker")

        # Create a failing function
# REMOVED_SYNTAX_ERROR: async def failing_function():
    # REMOVED_SYNTAX_ERROR: raise Exception("Test error")

    # Create a working function
# REMOVED_SYNTAX_ERROR: async def working_function():
    # REMOVED_SYNTAX_ERROR: await asyncio.sleep(0)
    # REMOVED_SYNTAX_ERROR: return "success"

    # Cause failures to open the circuit
    # REMOVED_SYNTAX_ERROR: for i in range(5):  # Failure threshold is 5
    # REMOVED_SYNTAX_ERROR: try:
        # REMOVED_SYNTAX_ERROR: await breaker.call(failing_function)
        # REMOVED_SYNTAX_ERROR: except Exception:
            # REMOVED_SYNTAX_ERROR: pass

            # Verify circuit is open
            # REMOVED_SYNTAX_ERROR: assert breaker.is_open == True, "Circuit should be open after 5 failures"

            # Try to call with open circuit - should fail
            # REMOVED_SYNTAX_ERROR: with pytest.raises(Exception) as exc_info:
                # REMOVED_SYNTAX_ERROR: await breaker.call(working_function)
                # REMOVED_SYNTAX_ERROR: assert "Circuit breaker test_breaker is open" in str(exc_info.value)

                # Wait for recovery timeout (30 seconds in production, but we'll patch for testing)
                # REMOVED_SYNTAX_ERROR: breaker.recovery_timeout = 1  # Override to 1 second for testing
                # REMOVED_SYNTAX_ERROR: breaker.opened_at = time.time() - 2  # Simulate 2 seconds have passed

                # Now the circuit should recover and allow the call
                # REMOVED_SYNTAX_ERROR: result = await breaker.call(working_function)
                # REMOVED_SYNTAX_ERROR: assert result == "success", "Circuit should have recovered and allowed the call"
                # REMOVED_SYNTAX_ERROR: assert breaker.is_open == False, "Circuit should be closed after recovery"
                # REMOVED_SYNTAX_ERROR: assert breaker.failure_count == 0, "Failure count should reset after recovery"

                # Removed problematic line: @pytest.mark.asyncio
                # Removed problematic line: async def test_unified_circuit_breaker_replaces_mock(self):
                    # REMOVED_SYNTAX_ERROR: """Verify UnifiedCircuitBreaker is used instead of MockCircuitBreaker."""
                    # REMOVED_SYNTAX_ERROR: pass
                    # REMOVED_SYNTAX_ERROR: manager = AuthCircuitBreakerManager()

                    # Get a breaker - should be UnifiedCircuitBreaker not MockCircuitBreaker
                    # REMOVED_SYNTAX_ERROR: breaker = manager.get_breaker("test_breaker")

                    # Verify it's UnifiedCircuitBreaker
                    # REMOVED_SYNTAX_ERROR: assert isinstance(breaker, UnifiedCircuitBreaker), \
                    # REMOVED_SYNTAX_ERROR: "Manager should create UnifiedCircuitBreaker, not MockCircuitBreaker"

                    # Verify it has proper configuration
                    # REMOVED_SYNTAX_ERROR: assert breaker.config.failure_threshold == 5, "Should have failure threshold of 5"
                    # REMOVED_SYNTAX_ERROR: assert breaker.config.recovery_timeout == 30, "Should have 30s recovery timeout"
                    # REMOVED_SYNTAX_ERROR: assert breaker.config.exponential_backoff == True, "Should use exponential backoff"

                    # Removed problematic line: @pytest.mark.asyncio
                    # Removed problematic line: async def test_unified_circuit_breaker_recovery_flow(self):
                        # REMOVED_SYNTAX_ERROR: """Test the complete recovery flow with UnifiedCircuitBreaker."""
                        # REMOVED_SYNTAX_ERROR: config = UnifiedCircuitConfig( )
                        # REMOVED_SYNTAX_ERROR: name="test",
                        # REMOVED_SYNTAX_ERROR: failure_threshold=3,  # Lower for testing
                        # REMOVED_SYNTAX_ERROR: recovery_timeout=1,    # 1 second for testing
                        # REMOVED_SYNTAX_ERROR: success_threshold=1    # 1 success to close from half-open
                        
                        # REMOVED_SYNTAX_ERROR: breaker = UnifiedCircuitBreaker(config)

                        # Failing function
# REMOVED_SYNTAX_ERROR: async def failing_func():
    # REMOVED_SYNTAX_ERROR: raise Exception("Test failure")

    # Working function
# REMOVED_SYNTAX_ERROR: async def working_func():
    # REMOVED_SYNTAX_ERROR: await asyncio.sleep(0)
    # REMOVED_SYNTAX_ERROR: return "success"

    # Phase 1: Circuit is CLOSED
    # REMOVED_SYNTAX_ERROR: assert breaker.state == UnifiedCircuitBreakerState.CLOSED

    # Phase 2: Cause failures to open circuit
    # REMOVED_SYNTAX_ERROR: for i in range(3):
        # REMOVED_SYNTAX_ERROR: try:
            # REMOVED_SYNTAX_ERROR: await breaker.call(failing_func)
            # REMOVED_SYNTAX_ERROR: except:
                # REMOVED_SYNTAX_ERROR: pass

                # Circuit should be OPEN
                # REMOVED_SYNTAX_ERROR: assert breaker.state == UnifiedCircuitBreakerState.OPEN

                # Calls should fail immediately when open
                # REMOVED_SYNTAX_ERROR: with pytest.raises(Exception) as exc_info:
                    # REMOVED_SYNTAX_ERROR: await breaker.call(working_func)
                    # REMOVED_SYNTAX_ERROR: assert "Circuit breaker" in str(exc_info.value)

                    # Phase 3: Wait for recovery timeout
                    # REMOVED_SYNTAX_ERROR: await asyncio.sleep(1.1)  # Wait slightly more than recovery timeout

                    # Phase 4: Circuit should transition to HALF_OPEN on next call attempt
                    # First successful call should close the circuit
                    # REMOVED_SYNTAX_ERROR: result = await breaker.call(working_func)
                    # REMOVED_SYNTAX_ERROR: assert result == "success"

                    # Circuit should be CLOSED again
                    # REMOVED_SYNTAX_ERROR: assert breaker.state == UnifiedCircuitBreakerState.CLOSED

                    # Removed problematic line: @pytest.mark.asyncio
                    # Removed problematic line: async def test_auth_client_handles_circuit_breaker_recovery(self):
                        # REMOVED_SYNTAX_ERROR: """Test that AuthServiceClient properly handles circuit breaker recovery."""
                        # REMOVED_SYNTAX_ERROR: pass
                        # REMOVED_SYNTAX_ERROR: client = AuthServiceClient()

                        # Test actual circuit breaker behavior with real breaker
                        # REMOVED_SYNTAX_ERROR: breaker = client.circuit_manager.get_breaker("_validate_token_remote_breaker")

                        # Force circuit to open by causing failures
# REMOVED_SYNTAX_ERROR: async def failing_operation():
    # REMOVED_SYNTAX_ERROR: pass
    # REMOVED_SYNTAX_ERROR: raise Exception("Service unavailable")

    # Cause enough failures to open circuit
    # REMOVED_SYNTAX_ERROR: failure_threshold = 5 if isinstance(breaker, MockCircuitBreaker) else breaker.config.failure_threshold
    # REMOVED_SYNTAX_ERROR: for i in range(failure_threshold):
        # REMOVED_SYNTAX_ERROR: try:
            # REMOVED_SYNTAX_ERROR: await breaker.call(failing_operation)
            # REMOVED_SYNTAX_ERROR: except Exception:
                # REMOVED_SYNTAX_ERROR: pass

                # Verify circuit is open
                # REMOVED_SYNTAX_ERROR: if isinstance(breaker, MockCircuitBreaker):
                    # REMOVED_SYNTAX_ERROR: assert breaker.is_open == True
                    # REMOVED_SYNTAX_ERROR: else:
                        # REMOVED_SYNTAX_ERROR: assert breaker.state == UnifiedCircuitBreakerState.OPEN

                        # Test fallback behavior with real error handler
                        # REMOVED_SYNTAX_ERROR: error_handler = UnifiedErrorHandler()

                        # REMOVED_SYNTAX_ERROR: try:
                            # Should handle the circuit breaker error gracefully
                            # REMOVED_SYNTAX_ERROR: await breaker.call(lambda x: None {"valid": True})
                            # REMOVED_SYNTAX_ERROR: except Exception as e:
                                # Error handler should provide meaningful error context
                                # REMOVED_SYNTAX_ERROR: error_context = error_handler.create_error_context( )
                                # REMOVED_SYNTAX_ERROR: error=e,
                                # REMOVED_SYNTAX_ERROR: operation="token_validation",
                                # REMOVED_SYNTAX_ERROR: component="circuit_breaker"
                                
                                # REMOVED_SYNTAX_ERROR: assert "Circuit breaker" in str(error_context.details)

                                # Removed problematic line: @pytest.mark.asyncio
                                # Removed problematic line: async def test_no_permanent_failure_states(self):
                                    # REMOVED_SYNTAX_ERROR: """Verify no components enter permanent failure states."""
                                    # This is a meta-test to ensure the pattern is fixed

                                    # Test 1: MockCircuitBreaker has recovery
                                    # REMOVED_SYNTAX_ERROR: mock_breaker = MockCircuitBreaker("test")
                                    # REMOVED_SYNTAX_ERROR: assert hasattr(mock_breaker, 'recovery_timeout'), "MockCircuitBreaker must have recovery_timeout"
                                    # REMOVED_SYNTAX_ERROR: assert hasattr(mock_breaker, 'failure_threshold'), "MockCircuitBreaker must have failure_threshold"
                                    # REMOVED_SYNTAX_ERROR: assert mock_breaker.recovery_timeout > 0, "Recovery timeout must be positive"
                                    # REMOVED_SYNTAX_ERROR: assert mock_breaker.failure_threshold > 1, "Failure threshold must be > 1"

                                    # Test 2: AuthCircuitBreakerManager creates proper breakers
                                    # REMOVED_SYNTAX_ERROR: manager = AuthCircuitBreakerManager()
                                    # REMOVED_SYNTAX_ERROR: breaker = manager.get_breaker("test")

                                    # Should be UnifiedCircuitBreaker with recovery
                                    # REMOVED_SYNTAX_ERROR: if isinstance(breaker, UnifiedCircuitBreaker):
                                        # REMOVED_SYNTAX_ERROR: assert breaker.config.recovery_timeout > 0, "UnifiedCircuitBreaker must have recovery timeout"
                                        # REMOVED_SYNTAX_ERROR: elif isinstance(breaker, MockCircuitBreaker):
                                            # If still using MockCircuitBreaker, it must have our fixes
                                            # REMOVED_SYNTAX_ERROR: assert breaker.recovery_timeout > 0, "MockCircuitBreaker must have recovery timeout"
                                            # REMOVED_SYNTAX_ERROR: assert breaker.failure_threshold > 1, "MockCircuitBreaker must have failure threshold"

                                            # Removed problematic line: @pytest.mark.asyncio
                                            # Removed problematic line: async def test_cascade_failure_prevention(self):
                                                # REMOVED_SYNTAX_ERROR: """Verify that one service failure doesn't cascade to permanent system failure."""
                                                # REMOVED_SYNTAX_ERROR: pass
                                                # Test with real AuthServiceClient and error handling
                                                # REMOVED_SYNTAX_ERROR: client = AuthServiceClient()
                                                # REMOVED_SYNTAX_ERROR: error_handler = UnifiedErrorHandler()

                                                # Test actual resilience patterns without mocking
                                                # REMOVED_SYNTAX_ERROR: breaker = client.circuit_manager.get_breaker("_validate_token_remote_breaker")

                                                # Simulate service failures that should trigger fallback
# REMOVED_SYNTAX_ERROR: async def failing_validation():
    # REMOVED_SYNTAX_ERROR: pass
    # REMOVED_SYNTAX_ERROR: raise Exception("Connection refused")

    # Cause failures but verify graceful degradation
    # REMOVED_SYNTAX_ERROR: for i in range(3):
        # REMOVED_SYNTAX_ERROR: try:
            # REMOVED_SYNTAX_ERROR: await breaker.call(failing_validation)
            # REMOVED_SYNTAX_ERROR: except Exception as e:
                # Should handle gracefully with error context
                # REMOVED_SYNTAX_ERROR: error_context = error_handler.create_error_context( )
                # REMOVED_SYNTAX_ERROR: error=e,
                # REMOVED_SYNTAX_ERROR: operation="token_validation",
                # REMOVED_SYNTAX_ERROR: component="auth_service"
                
                # REMOVED_SYNTAX_ERROR: assert error_context is not None
                # REMOVED_SYNTAX_ERROR: assert error_context.category in ["NETWORK", "SERVICE_UNAVAILABLE", "TIMEOUT"]

                # Verify system can still provide fallback responses
                # Even when circuit is open, system should degrade gracefully
                # REMOVED_SYNTAX_ERROR: try:
                    # REMOVED_SYNTAX_ERROR: result = await client.validate_token("test_token")
                    # Either succeeds or fails with proper error context - no permanent failure
                    # REMOVED_SYNTAX_ERROR: assert True  # Test passes if no unhandled exceptions


                    # REMOVED_SYNTAX_ERROR: @pytest.mark.mission_critical
# REMOVED_SYNTAX_ERROR: class TestSystemRecovery:
    # REMOVED_SYNTAX_ERROR: """Mission critical tests for system-wide recovery patterns."""

    # Removed problematic line: @pytest.mark.asyncio
    # Removed problematic line: async def test_error_behind_error_pattern(self):
        # REMOVED_SYNTAX_ERROR: '''
        # REMOVED_SYNTAX_ERROR: Test that we correctly identify "the error behind the error".

        # REMOVED_SYNTAX_ERROR: The AUTH failures were actually CIRCUIT BREAKER failures.
        # REMOVED_SYNTAX_ERROR: The "Invalid token" errors were actually "Circuit breaker open" errors.
        # REMOVED_SYNTAX_ERROR: '''
        # REMOVED_SYNTAX_ERROR: pass
        # REMOVED_SYNTAX_ERROR: client = AuthServiceClient()
        # REMOVED_SYNTAX_ERROR: error_handler = UnifiedErrorHandler()

        # Test real error chain identification
        # 1. Simulate missing SERVICE_SECRET from environment
        # REMOVED_SYNTAX_ERROR: original_secret = get_env("SERVICE_SECRET", None)

        # REMOVED_SYNTAX_ERROR: try:
            # Force configuration error
            # REMOVED_SYNTAX_ERROR: client.service_secret = None

            # 2. This should trigger cascade of errors
            # REMOVED_SYNTAX_ERROR: breaker = client.circuit_manager.get_breaker("_validate_token_remote_breaker")

            # Simulate failures that open circuit breaker
# REMOVED_SYNTAX_ERROR: async def config_error_operation():
    # REMOVED_SYNTAX_ERROR: pass
    # REMOVED_SYNTAX_ERROR: if not client.service_secret:
        # REMOVED_SYNTAX_ERROR: raise ValueError("Missing SERVICE_SECRET configuration")
        # REMOVED_SYNTAX_ERROR: await asyncio.sleep(0)
        # REMOVED_SYNTAX_ERROR: return {"valid": True}

        # Cause enough failures to open circuit
        # REMOVED_SYNTAX_ERROR: failure_count = 0
        # REMOVED_SYNTAX_ERROR: for i in range(6):  # Exceed typical failure threshold
        # REMOVED_SYNTAX_ERROR: try:
            # REMOVED_SYNTAX_ERROR: await breaker.call(config_error_operation)
            # REMOVED_SYNTAX_ERROR: except Exception as e:
                # REMOVED_SYNTAX_ERROR: failure_count += 1
                # Track the error chain properly
                # REMOVED_SYNTAX_ERROR: error_context = error_handler.create_error_context( )
                # REMOVED_SYNTAX_ERROR: error=e,
                # REMOVED_SYNTAX_ERROR: operation="token_validation",
                # REMOVED_SYNTAX_ERROR: component="configuration"
                

                # Verify we identify root cause not just symptom
                # REMOVED_SYNTAX_ERROR: if "Missing SERVICE_SECRET" in str(e):
                    # REMOVED_SYNTAX_ERROR: assert error_context.category == "CONFIGURATION"
                    # REMOVED_SYNTAX_ERROR: elif failure_count >= 5 and isinstance(breaker, MockCircuitBreaker) and breaker.is_open:
                        # Should identify circuit breaker as secondary issue
                        # REMOVED_SYNTAX_ERROR: assert "Circuit breaker" in str(e) or error_context.category == "SERVICE_UNAVAILABLE"

                        # Test actual token validation with proper error identification
                        # REMOVED_SYNTAX_ERROR: result = await client.validate_token("valid_token")

                        # Should identify configuration as root cause, not token validity
                        # REMOVED_SYNTAX_ERROR: if result and not result.get("valid"):
                            # REMOVED_SYNTAX_ERROR: error_msg = result.get("error", "")
                            # Error should point to real issue (config/service) not just "invalid token"
                            # REMOVED_SYNTAX_ERROR: assert "configuration" in error_msg.lower() or "service" in error_msg.lower() or "unreachable" in error_msg.lower()

                            # REMOVED_SYNTAX_ERROR: finally:
                                # Restore original configuration if it existed
                                # REMOVED_SYNTAX_ERROR: if original_secret:
                                    # REMOVED_SYNTAX_ERROR: client.service_secret = original_secret

                                    # Removed problematic line: @pytest.mark.asyncio
                                    # Removed problematic line: async def test_recovery_after_configuration_fix(self):
                                        # REMOVED_SYNTAX_ERROR: """Test that system recovers after configuration is fixed."""
                                        # REMOVED_SYNTAX_ERROR: client = AuthServiceClient()

                                        # Test real configuration recovery without mocking
                                        # REMOVED_SYNTAX_ERROR: original_secret = client.service_secret

                                        # REMOVED_SYNTAX_ERROR: try:
                                            # Start with missing SERVICE_SECRET
                                            # REMOVED_SYNTAX_ERROR: client.service_secret = None

                                            # Circuit breaker opens due to auth failures
                                            # REMOVED_SYNTAX_ERROR: breaker = client.circuit_manager.get_breaker("_validate_token_remote_breaker")

                                            # Cause real failures
# REMOVED_SYNTAX_ERROR: async def config_dependent_operation():
    # REMOVED_SYNTAX_ERROR: if not client.service_secret:
        # REMOVED_SYNTAX_ERROR: raise ValueError("Service secret not configured")
        # REMOVED_SYNTAX_ERROR: await asyncio.sleep(0)
        # REMOVED_SYNTAX_ERROR: return {"valid": True, "user_id": "123"}

        # Cause failures to open circuit
        # REMOVED_SYNTAX_ERROR: for i in range(6):
            # REMOVED_SYNTAX_ERROR: try:
                # REMOVED_SYNTAX_ERROR: await breaker.call(config_dependent_operation)
                # REMOVED_SYNTAX_ERROR: except Exception:
                    # REMOVED_SYNTAX_ERROR: pass

                    # Verify circuit is open (if MockCircuitBreaker)
                    # REMOVED_SYNTAX_ERROR: if isinstance(breaker, MockCircuitBreaker):
                        # REMOVED_SYNTAX_ERROR: assert breaker.is_open == True
                        # Set recovery timeout for testing
                        # REMOVED_SYNTAX_ERROR: breaker.recovery_timeout = 1
                        # REMOVED_SYNTAX_ERROR: breaker.opened_at = time.time()

                        # Fix the configuration
                        # REMOVED_SYNTAX_ERROR: client.service_secret = "fixed_secret_for_testing"

                        # Wait for recovery timeout
                        # REMOVED_SYNTAX_ERROR: await asyncio.sleep(1.1)

                        # Test actual recovery without patching
                        # REMOVED_SYNTAX_ERROR: if isinstance(breaker, MockCircuitBreaker):
                            # Force recovery check by attempting call
                            # REMOVED_SYNTAX_ERROR: try:
                                # REMOVED_SYNTAX_ERROR: result = await breaker.call(config_dependent_operation)
                                # If we reach here, circuit recovered and operation succeeded
                                # REMOVED_SYNTAX_ERROR: assert result is not None
                                # REMOVED_SYNTAX_ERROR: assert result.get("valid") == True
                                # REMOVED_SYNTAX_ERROR: except Exception as e:
                                    # If still failing, verify it's not due to permanent circuit state
                                    # REMOVED_SYNTAX_ERROR: if "Circuit breaker" in str(e):
                                        # Check if recovery timeout was respected
                                        # REMOVED_SYNTAX_ERROR: current_time = time.time()
                                        # REMOVED_SYNTAX_ERROR: assert current_time - breaker.opened_at >= breaker.recovery_timeout
                                        # REMOVED_SYNTAX_ERROR: else:
                                            # Test with UnifiedCircuitBreaker
                                            # REMOVED_SYNTAX_ERROR: result = await breaker.call(config_dependent_operation)
                                            # REMOVED_SYNTAX_ERROR: assert result is not None
                                            # REMOVED_SYNTAX_ERROR: assert result.get("valid") == True

                                            # REMOVED_SYNTAX_ERROR: finally:
                                                # Restore original configuration
                                                # REMOVED_SYNTAX_ERROR: client.service_secret = original_secret


                                                # REMOVED_SYNTAX_ERROR: if __name__ == "__main__":
                                                    # Run the mission critical tests
                                                    # REMOVED_SYNTAX_ERROR: pytest.main([__file__, "-v", "-m", "mission_critical"])
                                                    # REMOVED_SYNTAX_ERROR: pass